<?xml version="1.0" encoding="utf-8"?>
<!-- This URDF was automatically created by SolidWorks to URDF Exporter! Originally created by Stephen Brawner (brawner@gmail.com) 
     Commit Version: 1.6.0-4-g7f85cfe  Build Version: 1.6.7995.38578
     For more information, please see http://wiki.ros.org/sw_urdf_exporter -->
<robot
  name="robo_description">
  <link
    name="base_link">
    <inertial>
      <origin
        xyz="0.0088984 6.0231E-06 0.0077727"
        rpy="0 0 0" />
      <mass
        value="0.3102" />
      <inertia
        ixx="0.0004091"
        ixy="9.9283E-09"
        ixz="-7.307E-07"
        iyy="0.0012541"
        iyz="-3.3488E-10"
        izz="0.0016461" />
    </inertial>
    <visual>
      <origin
        xyz="0 0 0"
        rpy="0 0 0" />
      <geometry>
        <mesh
          filename="package://robo_description/meshes/visualbase_link.STL" />
      </geometry>
      <material
        name="">
        <color
          rgba="0.75294 0.75294 0.75294 1" />
      </material>
    </visual>
    <collision>
      <origin
        xyz="0 0 0"
        rpy="0 0 0" />
      <geometry>
        <mesh
          filename="package://robo_description/meshes/visualbase_link.STL" />
      </geometry>
    </collision>
  </link>
  <link
    name="robot_link1">
    <inertial>
      <origin
        xyz="-0.009918 -8.173E-05 0.014433"
        rpy="0 0 0" />
      <mass
        value="0.014963" />
      <inertia
        ixx="2.2152E-06"
        ixy="3.4307E-09"
        ixz="2.0019E-07"
        iyy="2.9119E-06"
        iyz="-5.3079E-11"
        izz="3.5724E-06" />
    </inertial>
    <visual>
      <origin
        xyz="0 0 0"
        rpy="0 0 0" />
      <geometry>
        <mesh
          filename="package://robo_description/meshes/visualrobot_link1.STL" />
      </geometry>
      <material
        name="">
        <color
          rgba="0.75294 0.75294 0.75294 1" />
      </material>
    </visual>
    <collision>
      <origin
        xyz="0 0 0"
        rpy="0 0 0" />
      <geometry>
        <mesh
          filename="package://robo_description/meshes/visualrobot_link1.STL" />
      </geometry>
    </collision>
  </link>
  <joint
    name="robot_joint1"
    type="revolute">
    <origin
      xyz="0.080093 4.1073E-05 0.05375"
      rpy="0 0 0" />
    <parent
      link="base_link" />
    <child
      link="robot_link1" />
    <axis
      xyz="0 0 1" />
    <limit
      lower="-3.1"
      upper="3.1"
      effort="30"
      velocity="50" />
  </joint>
  <link
    name="robot_link2">
    <inertial>
      <origin
        xyz="-1.2835E-05 0.040706 1.1431E-05"
        rpy="0 0 0" />
      <mass
        value="0.010238" />
      <inertia
        ixx="7.1442E-06"
        ixy="6.7805E-09"
        ixz="-2.4152E-09"
        iyy="5.2264E-06"
        iyz="7.2667E-10"
        izz="2.6243E-06" />
    </inertial>
    <visual>
      <origin
        xyz="0 0 0"
        rpy="0 0 0" />
      <geometry>
        <mesh
          filename="package://robo_description/meshes/visualrobot_link2.STL" />
      </geometry>
      <material
        name="">
        <color
          rgba="0.75294 0.75294 0.75294 1" />
      </material>
    </visual>
    <collision>
      <origin
        xyz="0 0 0"
        rpy="0 0 0" />
      <geometry>
        <mesh
          filename="package://robo_description/meshes/visualrobot_link2.STL" />
      </geometry>
    </collision>
  </link>
  <joint
    name="robot_joint2"
    type="revolute">
    <origin
      xyz="-0.00080355 -0.0002 0.017887"
      rpy="1.5705 0 -0.00053478" />
    <parent
      link="robot_link1" />
    <child
      link="robot_link2" />
    <axis
      xyz="0 0 -1" />
    <limit
      lower="-3.1"
      upper="3.1"
      effort="30"
      velocity="50" />
  </joint>
  <link
    name="robot_link3">
    <inertial>
      <origin
        xyz="-1.7051E-14 0.036675 -0.00011011"
        rpy="0 0 0" />
      <mass
        value="0.027294" />
      <inertia
        ixx="5.6327E-06"
        ixy="9.4982E-13"
        ixz="-1.4752E-20"
        iyy="3.3665E-06"
        iyz="-6.6047E-20"
        izz="4.458E-06" />
    </inertial>
    <visual>
      <origin
        xyz="0 0 0"
        rpy="0 0 0" />
      <geometry>
        <mesh
          filename="package://robo_description/meshes/visualrobot_link3.STL" />
      </geometry>
      <material
        name="">
        <color
          rgba="0.75294 0.75294 0.75294 1" />
      </material>
    </visual>
    <collision>
      <origin
        xyz="0 0 0"
        rpy="0 0 0" />
      <geometry>
        <mesh
          filename="package://robo_description/meshes/visualrobot_link3.STL" />
      </geometry>
    </collision>
  </link>
  <joint
    name="robot_joint3"
    type="revolute">
    <origin
      xyz="-1.2835E-05 0.081406 2.2853E-05"
      rpy="0.00028065 0.00053478 0" />
    <parent
      link="robot_link2" />
    <child
      link="robot_link3" />
    <axis
      xyz="0 0 -1" />
    <limit
      lower="-3.1"
      upper="3.1"
      effort="30"
      velocity="50" />
  </joint>
  <link
    name="robot_link4">
    <inertial>
      <origin
        xyz="0.0073483 0.041489 2.5381E-05"
        rpy="0 0 0" />
      <mass
        value="0.019954" />
      <inertia
        ixx="4.7409E-06"
        ixy="-6.9441E-07"
        ixz="1.1429E-08"
        iyy="5.038E-06"
        iyz="2.0471E-11"
        izz="4.9202E-06" />
    </inertial>
    <visual>
      <origin
        xyz="0 0 0"
        rpy="0 0 0" />
      <geometry>
        <mesh
          filename="package://robo_description/meshes/visualrobot_link4.STL" />
      </geometry>
      <material
        name="">
        <color
          rgba="0.75294 0.75294 0.75294 1" />
      </material>
    </visual>
    <collision>
      <origin
        xyz="0 0 0"
        rpy="0 0 0" />
      <geometry>
        <mesh
          filename="package://robo_description/meshes/visualrobot_link4.STL" />
      </geometry>
    </collision>
  </link>
  <joint
    name="robot_joint4"
    type="revolute">
    <origin
      xyz="0 0.07335 -0.00045"
      rpy="0 0 0" />
    <parent
      link="robot_link3" />
    <child
      link="robot_link4" />
    <axis
      xyz="0 0 -1" />
    <limit
      lower="-3.1"
      upper="3.1"
      effort="30"
      velocity="50" />
  </joint>
  <link
    name="hand_link">
    <inertial>
      <origin
        xyz="1.2557E-05 0.00018482 0.014397"
        rpy="0 0 0" />
      <mass
        value="0.015548" />
      <inertia
        ixx="3.1464E-06"
        ixy="3.3701E-09"
        ixz="-1.6327E-12"
        iyy="3.004E-06"
        iyz="-2.3373E-07"
        izz="4.4863E-06" />
    </inertial>
    <visual>
      <origin
        xyz="0 0 0"
        rpy="0 0 0" />
      <geometry>
        <mesh
          filename="package://robo_description/meshes/visualhand_link.STL" />
      </geometry>
      <material
        name="">
        <color
          rgba="0.75294 0.75294 0.75294 1" />
      </material>
    </visual>
    <collision>
      <origin
        xyz="0 0 0"
        rpy="0 0 0" />
      <geometry>
        <mesh
          filename="package://robo_description/meshes/visualhand_link.STL" />
      </geometry>
    </collision>
  </link>
  <joint
    name="hand_joint"
    type="revolute">
    <origin
      xyz="0.001325 0.0678 0"
      rpy="-1.5708 0 0" />
    <parent
      link="robot_link4" />
    <child
      link="hand_link" />
    <axis
      xyz="0 0 -1" />
    <limit
      lower="-3.1"
      upper="3.1"
      effort="30"
      velocity="50" />
  </joint>
  <link
    name="left_link">
    <inertial>
      <origin
        xyz="0.00034588 0.033051 3.0225E-05"
        rpy="0 0 0" />
      <mass
        value="0.008697" />
      <inertia
        ixx="7.0328E-06"
        ixy="-4.0123E-07"
        ixz="-3.9706E-09"
        iyy="7.866E-07"
        iyz="-3.3392E-08"
        izz="6.772E-06" />
    </inertial>
    <visual>
      <origin
        xyz="0 0 0"
        rpy="0 0 0" />
      <geometry>
        <mesh
          filename="package://robo_description/meshes/visualleft_link.STL" />
      </geometry>
      <material
        name="">
        <color
          rgba="0.75294 0.75294 0.75294 1" />
      </material>
    </visual>
    <collision>
      <origin
        xyz="0 0 0"
        rpy="0 0 0" />
      <geometry>
        <mesh
          filename="package://robo_description/meshes/visualleft_link.STL" />
      </geometry>
    </collision>
  </link>
  <joint
    name="left_link"
    type="revolute">
    <origin
      xyz="0 -0.0105 0.019"
      rpy="1.5708 0 1.5708" />
    <parent
      link="hand_link" />
    <child
      link="left_link" />
    <axis
      xyz="0 0 -1" />
    <limit
      lower="-3.1"
      upper="3.1"
      effort="30"
      velocity="50" />
  </joint>
  <link
    name="right_link">
    <inertial>
      <origin
        xyz="0.00015717 0.031586 -3.3046E-05"
        rpy="0 0 0" />
      <mass
        value="0.0091663" />
      <inertia
        ixx="7.577E-06"
        ixy="-3.8068E-07"
        ixz="4.5586E-09"
        iyy="8.1884E-07"
        iyz="3.3926E-08"
        izz="7.2934E-06" />
    </inertial>
    <visual>
      <origin
        xyz="0 0 0"
        rpy="0 0 0" />
      <geometry>
        <mesh
          filename="package://robo_description/meshes/visualright_link.STL" />
      </geometry>
      <material
        name="">
        <color
          rgba="0.75294 0.75294 0.75294 1" />
      </material>
    </visual>
    <collision>
      <origin
        xyz="0 0 0"
        rpy="0 0 0" />
      <geometry>
        <mesh
          filename="package://robo_description/meshes/visualright_link.STL" />
      </geometry>
    </collision>
  </link>
  <joint
    name="right_joint"
    type="revolute">
    <origin
      xyz="0 0.0115 0.019"
      rpy="1.5708 0 -1.5708" />
    <parent
      link="hand_link" />
    <child
      link="right_link" />
    <axis
      xyz="0 0 -1" />
    <limit
      lower="-3.1"
      upper="3.1"
      effort="30"
      velocity="50" />
  </joint>
</robot>