<?xml version="1.0" encoding="utf-8"?>
<!-- This URDF was automatically created by SolidWorks to URDF Exporter! Originally created by Stephen Brawner (brawner@gmail.com) 
     Commit Version: 1.6.0-4-g7f85cfe  Build Version: 1.6.7995.38578
     For more information, please see http://wiki.ros.org/sw_urdf_exporter -->
<robot
  name="are1018_urdf">
  <link
    name="base_link">
    <inertial>
      <origin
        xyz="6.91778333542455E-09 -0.000987638055765809 0.00969950688294337"
        rpy="0 0 0" />
      <mass
        value="0.170234591037879" />
      <inertia
        ixx="0.000190344867929517"
        ixy="-1.49585044621151E-11"
        ixz="-2.87752206040831E-12"
        iyy="0.000209895117595717"
        iyz="-4.25280510149574E-08"
        izz="0.000385505347421722" />
    </inertial>
    <visual>
      <origin
        xyz="0 0 0"
        rpy="0 0 0" />
      <geometry>
        <mesh
          filename="package://are1018_urdf/meshes/visual/base_link.STL" />
      </geometry>
      <material
        name="">
        <color
          rgba="0.792156862745098 0.819607843137255 0.933333333333333 1" />
      </material>
    </visual>
    <collision>
      <origin
        xyz="0 0 0"
        rpy="0 0 0" />
      <geometry>
        <mesh
          filename="package://are1018_urdf/meshes/visual/base_link.STL" />
      </geometry>
    </collision>
  </link>
  <link
    name="link0">
    <inertial>
      <origin
        xyz="-0.000148686471246822 -0.0108477499496043 0.0127257064637936"
        rpy="0 0 0" />
      <mass
        value="0.0134533721751118" />
      <inertia
        ixx="2.84098753200003E-06"
        ixy="-3.43071595594812E-09"
        ixz="5.30738424474361E-11"
        iyy="2.18307388098522E-06"
        iyz="2.00194190669691E-07"
        izz="3.55990656348061E-06" />
    </inertial>
    <visual>
      <origin
        xyz="0 0 0"
        rpy="0 0 0" />
      <geometry>
        <mesh
          filename="package://are1018_urdf/meshes/visual/link0.STL" />
      </geometry>
      <material
        name="">
        <color
          rgba="0.792156862745098 0.819607843137255 0.933333333333333 1" />
      </material>
    </visual>
    <collision>
      <origin
        xyz="0 0 0"
        rpy="0 0 0" />
      <geometry>
        <mesh
          filename="package://are1018_urdf/meshes/visual/link0.STL" />
      </geometry>
    </collision>
  </link>
  <joint
    name="joint0"
    type="revolute">
    <origin
      xyz="0 -0.0025386 0.05375"
      rpy="0 0 0" />
    <parent
      link="base_link" />
    <child
      link="link0" />
    <axis
      xyz="0 0 -1" />
    <limit
      lower="-2"
      upper="2"
      effort="100"
      velocity="1" />
  </joint>
  <link
    name="link1">
    <inertial>
      <origin
        xyz="-2.62658044619668E-09 -0.0345571058935115 0.0254946423103066"
        rpy="0 0 0" />
      <mass
        value="0.0120579589553567" />
      <inertia
        ixx="7.19129614481569E-06"
        ixy="-6.77986390248771E-09"
        ixz="7.78451970892812E-21"
        iyy="5.27353232807871E-06"
        iyz="-2.09008873732233E-19"
        izz="2.71342255945596E-06" />
    </inertial>
    <visual>
      <origin
        xyz="0 0 0"
        rpy="0 0 0" />
      <geometry>
        <mesh
          filename="package://are1018_urdf/meshes/visual/link1.STL" />
      </geometry>
      <material
        name="">
        <color
          rgba="0.792156862745098 0.819607843137255 0.933333333333333 1" />
      </material>
    </visual>
    <collision>
      <origin
        xyz="0 0 0"
        rpy="0 0 0" />
      <geometry>
        <mesh
          filename="package://are1018_urdf/meshes/visual/link1.STL" />
      </geometry>
    </collision>
  </link>
  <joint
    name="joint1"
    type="revolute">
    <origin
      xyz="0.02575 -0.00081639 0.017894"
      rpy="-1.5708 0 1.5708" />
    <parent
      link="link0" />
    <child
      link="link1" />
    <axis
      xyz="0 0 1" />
    <limit
      lower="-0.9"
      upper="1.5"
      effort="100"
      velocity="1" />
  </joint>
  <link
    name="link2">
    <inertial>
      <origin
        xyz="0.0265477568891185 5.89201840095477E-10 0.0209223131306843"
        rpy="0 0 0" />
      <mass
        value="0.0163235420272894" />
      <inertia
        ixx="4.24056894578294E-06"
        ixy="3.38988499063713E-09"
        ixz="-3.36881501952228E-09"
        iyy="6.33118981534796E-06"
        iyz="-4.63361240339478E-15"
        izz="3.44644530707849E-06" />
    </inertial>
    <visual>
      <origin
        xyz="0 0 0"
        rpy="0 0 0" />
      <geometry>
        <mesh
          filename="package://are1018_urdf/meshes/visual/link2.STL" />
      </geometry>
      <material
        name="">
        <color
          rgba="0.792156862745098 0.819607843137255 0.933333333333333 1" />
      </material>
    </visual>
    <collision>
      <origin
        xyz="0 0 0"
        rpy="0 0 0" />
      <geometry>
        <mesh
          filename="package://are1018_urdf/meshes/visual/link2.STL" />
      </geometry>
    </collision>
  </link>
  <joint
    name="joint2"
    type="revolute">
    <origin
      xyz="0 -0.081399 0.00495"
      rpy="0 0 0" />
    <parent
      link="link1" />
    <child
      link="link2" />
    <axis
      xyz="0 0 1" />
    <limit
      lower="-3.14"
      upper="0.9"
      effort="100"
      velocity="1" />
  </joint>
  <link
    name="link3">
    <inertial>
      <origin
        xyz="0.0338316024275452 -8.95955161251544E-05 0.0210634009704761"
        rpy="0 0 0" />
      <mass
        value="0.0266121463125793" />
      <inertia
        ixx="6.11128645475265E-06"
        ixy="-1.41339391021082E-12"
        ixz="-2.37103119931184E-07"
        iyy="5.9084006432695E-06"
        iyz="3.3192141647198E-09"
        izz="5.13314117763412E-06" />
    </inertial>
    <visual>
      <origin
        xyz="0 0 0"
        rpy="0 0 0" />
      <geometry>
        <mesh
          filename="package://are1018_urdf/meshes/visual/link3.STL" />
      </geometry>
      <material
        name="">
        <color
          rgba="0.792156862745098 0.819607843137255 0.933333333333333 1" />
      </material>
    </visual>
    <collision>
      <origin
        xyz="0 0 0"
        rpy="0 0 0" />
      <geometry>
        <mesh
          filename="package://are1018_urdf/meshes/visual/link3.STL" />
      </geometry>
    </collision>
  </link>
  <joint
    name="joint3"
    type="revolute">
    <origin
      xyz="0.077374 0 0"
      rpy="0 0 0" />
    <parent
      link="link2" />
    <child
      link="link3" />
    <axis
      xyz="0 0 1" />
    <limit
      lower="-2"
      upper="1.5"
      effort="100"
      velocity="1" />
  </joint>
  <link
    name="link4_0">
    <inertial>
      <origin
        xyz="0.0330511280658098 0.000272774366305122 -0.0266302052102281"
        rpy="0 0 0" />
      <mass
        value="0.0086970283014079" />
      <inertia
        ixx="7.84856466527092E-07"
        ixy="-3.87408492985789E-07"
        ixz="3.33950203699119E-08"
        iyy="7.03452850502723E-06"
        iyz="4.11048560512625E-09"
        izz="6.77200341516074E-06" />
    </inertial>
    <visual>
      <origin
        xyz="0 0 0"
        rpy="0 0 0" />
      <geometry>
        <mesh
          filename="package://are1018_urdf/meshes/visual/link4_0.STL" />
      </geometry>
      <material
        name="">
        <color
          rgba="0.792156862745098 0.819607843137255 0.933333333333333 1" />
      </material>
    </visual>
    <collision>
      <origin
        xyz="0 0 0"
        rpy="0 0 0" />
      <geometry>
        <mesh
          filename="package://are1018_urdf/meshes/visual/link4_0.STL" />
      </geometry>
    </collision>
  </link>
  <joint
    name="joint4_0"
    type="revolute">
    <origin
      xyz="0.053675 -0.0266 0.0103"
      rpy="1.5708 -0.01083 0" />
    <parent
      link="link3" />
    <child
      link="link4_0" />
    <axis
      xyz="0 0 -1" />
    <limit
      lower="0"
      upper="2"
      effort="100"
      velocity="1" />
  </joint>
  <link
    name="link4_1">
    <inertial>
      <origin
        xyz="0.031501735492723 -0.000501563206578234 -0.0314925232676157"
        rpy="0 0 0" />
      <mass
        value="0.0137369834582284" />
      <inertia
        ixx="1.23822723867815E-06"
        ixy="6.75819876123419E-07"
        ixz="-7.55665133610328E-07"
        iyy="1.12944276667532E-05"
        iyz="5.43864342855235E-08"
        izz="1.08894179820153E-05" />
    </inertial>
    <visual>
      <origin
        xyz="0 0 0"
        rpy="0 0 0" />
      <geometry>
        <mesh
          filename="package://are1018_urdf/meshes/visual/link4_1.STL" />
      </geometry>
      <material
        name="">
        <color
          rgba="0.792156862745098 0.819607843137255 0.933333333333333 1" />
      </material>
    </visual>
    <collision>
      <origin
        xyz="0 0 0"
        rpy="0 0 0" />
      <geometry>
        <mesh
          filename="package://are1018_urdf/meshes/visual/link4_1.STL" />
      </geometry>
    </collision>
  </link>
  <joint
    name="joint4_1"
    type="revolute">
    <origin
      xyz="0.053675 -0.0263 0.0323"
      rpy="1.5708 -0.010399 0" />
    <parent
      link="link3" />
    <child
      link="link4_1" />
    <axis
      xyz="0 0 -1" />
    <limit
      lower="-2"
      upper="0"
      effort="100"
      velocity="1" />
  </joint>
</robot>