<?xml version="1.0" encoding="utf-8"?>
<!-- This URDF was automatically created by SolidWorks to URDF Exporter! Originally created by Stephen Brawner (brawner@gmail.com) 
     Commit Version: 1.6.0-4-g7f85cfe  Build Version: 1.6.7995.38578
     For more information, please see http://wiki.ros.org/sw_urdf_exporter -->
<robot
  name="4dof">
  <link
    name="base_link">
    <inertial>
      <origin
        xyz="6.91716587489718E-09 -0.00812903865775771 -0.0403002903986256"
        rpy="0 0 0" />
      <mass
        value="0.170234591037879" />
      <inertia
        ixx="0.000190344867929517"
        ixy="-1.4958504458943E-11"
        ixz="-2.87752967188399E-12"
        iyy="0.000209895117595717"
        iyz="-4.25280510149466E-08"
        izz="0.000385505347421722" />
    </inertial>
    <visual>
      <origin
        xyz="0 0 0"
        rpy="0 0 0" />
      <geometry>
        <mesh
          filename="package://4dof/meshes/base_link.STL" />
      </geometry>
      <material
        name="">
        <color
          rgba="0.792156862745098 0.819607843137255 0.933333333333333 1" />
      </material>
    </visual>
    <collision>
      <origin
        xyz="0 0 0"
        rpy="0 0 0" />
      <geometry>
        <mesh
          filename="package://4dof/meshes/base_link.STL" />
      </geometry>
    </collision>
  </link>
  <link
    name="link0">
    <inertial>
      <origin
        xyz="-0.000148686471246819 -0.0108477499496043 0.0127257064637936"
        rpy="0 0 0" />
      <mass
        value="0.0134533721751118" />
      <inertia
        ixx="2.84098753200003E-06"
        ixy="-3.43071595594812E-09"
        ixz="5.30738424476259E-11"
        iyy="2.18307388098522E-06"
        iyz="2.00194190669691E-07"
        izz="3.55990656348061E-06" />
    </inertial>
    <visual>
      <origin
        xyz="0 0 0"
        rpy="0 0 0" />
      <geometry>
        <mesh
          filename="package://4dof/meshes/link0.STL" />
      </geometry>
      <material
        name="">
        <color
          rgba="0.792156862745098 0.819607843137255 0.933333333333333 1" />
      </material>
    </visual>
    <collision>
      <origin
        xyz="0 0 0"
        rpy="0 0 0" />
      <geometry>
        <mesh
          filename="package://4dof/meshes/link0.STL" />
      </geometry>
    </collision>
  </link>
  <joint
    name="joint0"
    type="revolute">
    <origin
      xyz="0 -0.00968 0.00375020271827014"
      rpy="0 0 0" />
    <parent
      link="base_link" />
    <child
      link="link0" />
    <axis
      xyz="0 0 -1" />
    <limit
      lower="-2"
      upper="2"
      effort="100"
      velocity="1" />
  </joint>
  <link
    name="link1">
    <inertial>
      <origin
        xyz="-2.6265804479314E-09 -0.0345571058935115 0.0254946423103066"
        rpy="0 0 0" />
      <mass
        value="0.0120579589553567" />
      <inertia
        ixx="7.19129614481569E-06"
        ixy="-6.77986390248771E-09"
        ixz="7.78052031035584E-21"
        iyy="5.27353232807871E-06"
        iyz="-2.08434447068504E-19"
        izz="2.71342255945596E-06" />
    </inertial>
    <visual>
      <origin
        xyz="0 0 0"
        rpy="0 0 0" />
      <geometry>
        <mesh
          filename="package://4dof/meshes/link1.STL" />
      </geometry>
      <material
        name="">
        <color
          rgba="0.792156862745098 0.819607843137255 0.933333333333333 1" />
      </material>
    </visual>
    <collision>
      <origin
        xyz="0 0 0"
        rpy="0 0 0" />
      <geometry>
        <mesh
          filename="package://4dof/meshes/link1.STL" />
      </geometry>
    </collision>
  </link>
  <joint
    name="joint1"
    type="revolute">
    <origin
      xyz="0.0257499999999922 -0.000816386290255001 0.0178942036737967"
      rpy="-1.57079632679482 0 1.5707963267949" />
    <parent
      link="link0" />
    <child
      link="link1" />
    <axis
      xyz="0 0 1" />
    <limit
      lower="-0.9"
      upper="1.5"
      effort="100"
      velocity="1" />
  </joint>
  <link
    name="link2">
    <inertial>
      <origin
        xyz="0.026548 5.892E-10 0.020922"
        rpy="0 0 0" />
      <mass
        value="0.016324" />
      <inertia
        ixx="4.2406E-06"
        ixy="3.3899E-09"
        ixz="-3.3688E-09"
        iyy="6.3312E-06"
        iyz="-4.6336E-15"
        izz="3.4464E-06" />
    </inertial>
    <visual>
      <origin
        xyz="0 0 0"
        rpy="0 0 0" />
      <geometry>
        <mesh
          filename="package://4dof/meshes/link2.STL" />
      </geometry>
      <material
        name="">
        <color
          rgba="0.79216 0.81961 0.93333 1" />
      </material>
    </visual>
    <collision>
      <origin
        xyz="0 0 0"
        rpy="0 0 0" />
      <geometry>
        <mesh
          filename="package://4dof/meshes/link2.STL" />
      </geometry>
    </collision>
  </link>
  <joint
    name="joint2"
    type="revolute">
    <origin
      xyz="0 -0.081399 0.00495"
      rpy="0 0 0" />
    <parent
      link="link1" />
    <child
      link="link2" />
    <axis
      xyz="0 0 1" />
    <limit
      lower="-3.14"
      upper="0.9"
      effort="100"
      velocity="1" />
  </joint>
  <link
    name="link3">
    <inertial>
      <origin
        xyz="0.033832 -8.9596E-05 0.021063"
        rpy="0 0 0" />
      <mass
        value="0.026612" />
      <inertia
        ixx="6.1113E-06"
        ixy="-1.4134E-12"
        ixz="-2.371E-07"
        iyy="5.9084E-06"
        iyz="3.3192E-09"
        izz="5.1331E-06" />
    </inertial>
    <visual>
      <origin
        xyz="0 0 0"
        rpy="0 0 0" />
      <geometry>
        <mesh
          filename="package://4dof/meshes/link3.STL" />
      </geometry>
      <material
        name="">
        <color
          rgba="0.79216 0.81961 0.93333 1" />
      </material>
    </visual>
    <collision>
      <origin
        xyz="0 0 0"
        rpy="0 0 0" />
      <geometry>
        <mesh
          filename="package://4dof/meshes/link3.STL" />
      </geometry>
    </collision>
  </link>
  <joint
    name="joint3"
    type="revolute">
    <origin
      xyz="0.077374 0 0"
      rpy="0 0 0" />
    <parent
      link="link2" />
    <child
      link="link3" />
    <axis
      xyz="0 0 1" />
    <limit
      lower="-2"
      upper="1.5"
      effort="100"
      velocity="1" />
  </joint>
  <link
    name="link4_0">
    <inertial>
      <origin
        xyz="-0.000630704493724666 0.0330462355514071 -0.0266302052102279"
        rpy="0 0 0" />
      <mass
        value="0.00869702830140787" />
      <inertia
        ixx="7.02540464572684E-06"
        ixy="4.54998048327262E-07"
        ixz="-4.47191504115758E-09"
        iyy="7.93980325827443E-07"
        iyz="3.33485449949403E-08"
        izz="6.77200341516071E-06" />
    </inertial>
    <visual>
      <origin
        xyz="0 0 0"
        rpy="0 0 0" />
      <geometry>
        <mesh
          filename="package://4dof/meshes/link4_0.STL" />
      </geometry>
      <material
        name="">
        <color
          rgba="0.792156862745098 0.819607843137255 0.933333333333333 1" />
      </material>
    </visual>
    <collision>
      <origin
        xyz="0 0 0"
        rpy="0 0 0" />
      <geometry>
        <mesh
          filename="package://4dof/meshes/link4_0.STL" />
      </geometry>
    </collision>
  </link>
  <joint
    name="joint4_0"
    type="revolute">
    <origin
      xyz="0.053675 -0.0266 0.0103"
      rpy="1.5708 1.5708 0" />
    <parent
      link="link3" />
    <child
      link="link4_0" />
    <axis
      xyz="0 0 -1" />
    <limit
      lower="0"
      upper="2"
      effort="100"
      velocity="1" />
  </joint>
  <link
    name="link4_1">
    <inertial>
      <origin
        xyz="0.000173958983292661 0.0315052478071499 -0.0314925232970695"
        rpy="0 0 0" />
      <mass
        value="0.0137369834821421" />
      <inertia
        ixx="1.13073948211714E-05"
        ixy="-5.71107992161234E-07"
        ixz="-4.65255642868619E-08"
        iyy="1.22526011553155E-06"
        iyz="-7.56189830117657E-07"
        izz="1.08894180109584E-05" />
    </inertial>
    <visual>
      <origin
        xyz="0 0 0"
        rpy="0 0 0" />
      <geometry>
        <mesh
          filename="package://4dof/meshes/link4_1.STL" />
      </geometry>
      <material
        name="">
        <color
          rgba="0.792156862745098 0.819607843137255 0.933333333333333 1" />
      </material>
    </visual>
    <collision>
      <origin
        xyz="0 0 0"
        rpy="0 0 0" />
      <geometry>
        <mesh
          filename="package://4dof/meshes/link4_1.STL" />
      </geometry>
    </collision>
  </link>
  <joint
    name="joint4_1"
    type="revolute">
    <origin
      xyz="0.0536750009340492 -0.0263000000000005 0.0322999999999996"
      rpy="1.5707963267949 1.5707963267949 0" />
    <parent
      link="link3" />
    <child
      link="link4_1" />
    <axis
      xyz="0 0 -1" />
    <limit
      lower="-2"
      upper="0"
      effort="100"
      velocity="1" />
  </joint>
</robot>